Workbook

Sheet Customers
A1: CustomerID | B1: FullName | C1: Email | D1: Phone | E1: Address | F1: SignupDate | G1: LoyaltyTier
A2: C-0001 | B2: Smith, John | C2: john.smith@example.com | D2: +1-555-123-4567 | E2: 221B Baker St, London, UK | F2: 2024-01-15 | G2: GOLD
A3: C-0002 | B3: Garcia, Ana | C3: ana.garcia at example.com | D3: +555-987-6543 | E3: Calle 123, Madrid, Spain | F3: 15/02/2024 | G3: silver
A4: C-0003 | B4: O'Neil, Pat | C4: pat.oneil@example | D4: +020-7946-0958 | E4: 142 Thomas, Shing, Ireland | F4: 08/05/2024
A5: C-0004 | B5: Zhang, Wei | C5: wei.zhang@example.com | D5: +86-10-6552-9988 | E5: No.8 Chaoyang, Beijing, China | F5: 2024.04.01 | G5: bronze
A6: C-0005 | B6: Di Franco, Luca | C6: luca.difranco@example.com | D6: +39-06-6982-1 | E6: Via Roma 10, Roma, Italy | F6: 1 May 2024 | G6: GOLD
A7: C-0006 | B7: Santos, Maria | C7: maria.santos at example.com | D7: +55-119-8765-4321 | E7: Av. Paulista, São Paulo, Brazil | F7: 2024-06-05
A8: C-0007 | B8: Ivanov, Olga | C8: olga.ivanov@example.com | D8: +7-495-123-4567 | E8: Tverskaya 7, Moscow, Russia | F8: 2024/06/12 | G8: PLATINUM
A9: C-0008 | B9: Khan, Aisha | C9: aisha.khan@example | D9: +91-987-654-3210 | E9: Bandra, Mumbai, India | F9: 12-07-2024 | G9: GOLD
A10: C-0009 | B10: Nguyen, Minh | C10: minh.nguyen at example.com | D10: +84-24-3825-2736 | E10: Hoan Kiem, Hanoi, Vietnam | F10: 2024-07-20 | G10: silver
A11: C-0010 | B11: Müller, Franz | C11: franz.muller@example.com | D11: +49-30-901820 | E11: Alexanderplatz, Berlin, Germany | F11: 2024-07-22 | G11: BRONZE
A12: C-0011 | B12: Chen, Li | C12: li.chen@example.com | D12: +86-21-6247-6666 | E12: Pudong, Shanghai, China | F12: 2024-08-01 | G12: bronze
A13: C-0012 | B13: Ali , Omar | C13: omar.ali@example.com | D13: +971-4-123-4567 | E13: Deira, Dubai, UAE | F13: 08/05/2024 | G13: GOLD
A14: C-0013 | B14: Rossi, Giulia | C14: giulia.rossi at example.com | D14: +39-02-123-4567 | E14: Duomo, Milano, Italy | F14: 2024-08-10 | G14: SILVER
A15: C-0014 | B15: Silva, Pedro | C15: pedro.silva@example.com | D15: +351 21 123 4567 | E15: Alameda, Lisboa, Portugal | F15: 2024-08-12 | G15: PLATINUM
A16: C-0015 | B16: Yamada, Kenji | C16: kenji.yamada@example.com | D16: +81-3-1234-5678 | E16: Shinjuku, Tokyo, Japan | F16: 2024-08-15 | G16: gold
A17: C-0016 | B17: Doe, Jane | C17: jane.doe@example.com | D17: +1-212-555-0199 | E17: Manhattan, New York, US | F17: 2024-08-18 | G17: Silver
A18: C-0017 | B18: Lee, Sara | C18: sara.lee@example.com | D18: +1-617-555-0100 | E18: Cambridge, MA, US | F18: 2024-09-01 | G18: Bronze
A19: C-0018 | B19: Kim, Jin | C19: jin.kim at example.com | D19: +82-2-312-3456 | E19: Seoul, Korea | F19: 2024-09-03 | G19: Platinum
A20: C-0019 | B20: Singh, Raj | C20: raj.singh@example.com | D20: +91-22-1234-5678 | E20: Mumbai, India | F20: 2024-09-05
A21: C-0020 | B21: Kowalski, Piotr | C21: piotr.k@example.com | D21: +48-22-695-7000 | E21: Warsaw, Poland | F21: 2024-09-08 | G21: Gold
A22: C-0021 | B22: Novák, Eva | C22: eva.novak at example.com | D22: +420-224-001-111 | E22: Prague, Czechia | F22: 2024-09-10 | G22: Silver
A23: C-0022 | B23: Hernández, Luis | C23: luis.hdz@example.com | D23: +34-91-123-4567 | E23: Madrid, Spain | F23: 2024-09-12 | G23: Bronze
A24: C-0023 | B24: Popescu, Andrei | C24: andrei.popescu@example.com | D24: +40-21-201-0200 | E24: Bucharest, Romania | F24: 2024-09-14
A25: C-0024 | B25: Ndiaye, Awa | C25: awa.ndiaye at example.com | D25: +221-33-839-5050 | E25: Dakar, Senegal | F25: 2024-09-16
A26: C-0025 | B26: Hassan, Noor | C26: noor.hassan@example.com | D26: +20-2-2794-2400 | E26: Cairo, Egypt | F26: 2024-09-18 | G26: Gold
A27: C-0026 | B27: Smith, John | C27: john.smith@example.com | D27: +39-06-6982-1 | E27: Via Roma 10, Roma, Italy | F27: 1 May 2024 | G27: Gold

Sheet Products
A1: ProductID | B1: ProductName | C1: CategorySubcategory | D1: SKU | E1: UnitPrice | F1: Cost | G1: Discontinued
A2: P-101 | B2: Bikes|Mountain Pro 27.5 | C2: Bikes|Mountain | D2: BIK-00123-XL | E2: USD 1999.00 | F2: 1500 | G2: No
A3: P-102 | B3: Bikes|Road Elite 700c | C3: Bikes|Road | D3: BIK-00456-L | E3: USD 2499.00 | F3: 2000 | G3: No
A4: P-103 | B4: Helmets - Trail | C4: Accessories|Safety | D4: ACC-TR-HELM-001 | E4: USD 79.99 | F4: 50 | G4: No
A5: P-104 | B5: Bottle:Camel 750ml | C5: Accessories|Hydration | D5: ACC-HY-0750 | E5: EUR 19.99 | F5: 17.5 | G5: No
A6: P-105 | B6: Gloves / Winter | C6: Accessories|Apparel | D6: ACC-AP-GLV-WI | E6: USD 34.50 | F6: 20 | G6: no
A7: P-106 | B7: Lights|Front-900lm | C7: Accessories|Lighting | D7: ACC-LI-FR-900 | E7: USD 89.00 | F7: 60 | G7: NO
A8: P-107 | B8: Lights|Rear - 200lm | C8: Accessories|Lighting | D8: ACC-LI-RR-200 | E8: USD 59.00 | F8: 40 | G8: No
A9: P-108 | B9: Pump: CO2 Mini | C9: Accessories|Tools | D9: ACC-TO-CO2-01 | E9: USD 25.00 | F9: 14 | G9: No
A10: P-109 | B10: Rack- Rear | C10: Accessories|Cargo | D10: ACC-CG-RK-RR | E10: USD 49.99 | F10: 35 | G10: No
A11: P-110 | B11: Lock | U-Bar | C11: Accessories|Security | D11: ACC-SC-UB-01 | E11: USD 39.99 | F11: 28 | G11: No
A12: P-111 | B12: Saddle:Gel-Comfort | C12: Accessories|Comfort | D12: ACC-CM-SDL-GE | E12: USD 69.99 | F12: 52 | G12: No
A13: P-112 | B13: Jersey-Men-L | C13: Apparel|Jersey | D13: APP-JRS-M-L | E13: USD 59.99 | F13: 43 | G13: No
A14: P-113 | B14: Jersey-Men-L | C14: Apparel|Jersey | D14: APP-JRS-M-L | E14: USD 59.99 | F14: 43 | G14: No
A15: P-114 | B15: Shorts-Women-M | C15: Apparel|Shorts | D15: APP-SHR-W-M | E15: USD 79.99 | F15: 55 | G15: No
A16: P-115 | B16: Shoes-MTB-42 | C16: Footwear|Shoes | D16: FTW-SHO-MTB-42 | E16: USD 129.99 | F16: 95 | G16: No
A17: P-116 | B17: Shoes-MTB-43 | C17: Footwear|Shoes | D17: FTW-SHO-MTB-43 | E17: USD 129.99 | F17: 95 | G17: No
... A27: P-126 | B27: Action Cam 4K | C27: Electronics|Camera | D27: ELE-CAM-4K | E27: USD 199.99 | F27: 150 | G27: No

Sheet Exchange Rates
A1: FromCurrency | B1: ToCurrency | C1: Rate
A2: USD | B2: EUR | C2: 0.92
A3: USD | B3: CAD | C3: 1.35
A4: USD | B4: USD | C4: 1
A6: USD | B6: EUR | C6: 0.92
A7: USD | B7: CAD | C7: 1.35

Sheet Stores
A1: StoreID | B1: StoreName | C1: RegionCode | D1: Address
A2: S-01 | B2: NovaGear London | C2: UK-LON | D2: London - LON - UK
A3: S-02 | B3: NovaGear Madrid | C3: ES-MD | D3: Madrid- MD - Spain
A4: S-03 | B4: NovaGear Beijing | C4: CN-BJ | D4: Beijing - BJ - China
A5: S-04 | B5: NovaGear Rome | C5: IT-RM | D5: Roma - RM - IT
A6: S-05 | B6: NovaGear São Paulo | C6: BR-SP | D6: São Paulo - SP - Brazil
A7: S-06 | B7: NovaGear Moscow | C7: RU-MOW | D7: Moscow - MOW - Russia
A8: S-07 | B8: NovaGear Mumbai | C8: IN-MH | D8: Mumbai - MH - India
A9: S-08 | B9: NovaGear Hanoi | C9: VN-HN | D9: Hanoi - HN - Vietnam
A10: S-09 | B10: NovaGear Berlin | C10: DE-BE | D10: Berlin - BE - Germany
A11: S-10 | B11: NovaGear Dubai | C11: AE-DXB | D11: Dubai - DXB - UAE

Sheet Orders
A1: OrderID | B1: CustomerID | C1: StoreID | D1: OrderDate | E1: Currency | F1: TotalAmount | G1: PaymentMethod | H1: OrderStatus
A2: O-1001 | B2: C-0023 | C2: S-06 | D2: 07/21/2024 | E2: CAD | F2: 1788.08 | G2: Card | H2: Completed
A3: O-1002 | B3: C-0004 | C3: S-05 | D3: 07/27/2024 | E3: EUR | F3: EUR 376.941 | G3: UPI | H3: Completed
A4: O-1003 | B4: C-0025 | C4: S-03 | D4: 2025-05-19 | E4: EUR | F4: EUR 376.941 | G4: Cash
A5: O-1004 | B5: C-0009 | C5: S-03 | D5: 2024-07-05 | E5: EUR | F5: 322.4415 | G5: Card | H5: Refunded
A6: O-1005 | B6: C-0023 | C6: S-02 | D6: 1 Aug 2024 | E6: CAD | F6: 161.973 | G6: Cash | H6: Completed
A7: O-1006 | B7: C-0018 | C7: S-01 | D7: 2024.07.21 | E7: CAD | F7: CAD 328.981 | G7: Wallet | H7: Pending
A8: O-1007 | B8: C-0001 | C8: S-02 | D8: 2025-05-14 | E8: CAD | F8: 231.932 | G8: Wallet | H8: Pending
A9: O-1008 | B9: C-0024 | C9: S-04 | D9: 2025-03-04 | E9: USD | F9: USD 279.95 | G9: Wallet | H9: Refunded
A10: O-1009 | B10: C-0017 | C10: S-09 | D10: 2024-07-01 | E10: EUR | F10: 389.97 | G10: Cash
A11: O-1010 | B11: C-0009 | C11: S-05 | D11: 2024-07-05 | E11: EUR | F11: 75.981 | G11: UPI | H11: Completed
A12: O-1011 | B12: C-0022 | C12: S-06 | D12: 2025-01-15 | E12: USD | F12: 2810.962 | G12: UPI
A13: O-1012 | B13: C-0005 | C13: S-03 | D13: 1 Aug 2024 | E13: EUR | F13: EUR 100 | G13: Wallet
A14: O-1013 | B14: C-0024 | C14: S-10 | D14: 2024-07-07 | E14: USD | F14: USD 2064.03 | G14: Cash | H14: Refunded
A15: O-1014 | B15: C-0005 | C15: S-04 | D15: 2024.07.17 | E15: USD | F15: 100 | G15: UPI
A16: O-1015 | B16: C-0011 | C16: S-07 | D16: 2024.07.19 | E16: USD | F16: USD 161.481 | G16: Cash | H16: Completed
A17: O-1016 | B17: C-0007 | C17: S-08 | D17: 2024-07-08 | E17: USD | F17: USD 44.98 | G17: Cash | H17: Completed
A18: O-1017 | B18: C-0003 | C18: S-09 | D18: 1 Aug 2024 | E18: CAD | F18: CAD 249.553 | G18: Card | H18: Completed
A19: O-1018 | B19: C-0020 | C19: S-05 | D19: 2024-07-03 | E19: USD | F19: 542.964 | G19: UPI
A20: O-1019 | B20: C-0003 | C20: S-08 | D20: 2025-02-02 | E20: USD | F20: 496.4535 | G20: Card | H20: Completed
A21: O-1020 | B21: C-0021 | C21: S-08 | D21: 2025-02-15 | E21: USD | F21: 253.65 | G21: Wallet | H21: Pending
A22: O-1021 | B22: C-0016 | C22: S-02 | D22: 2024-07-08 | E22: USD | F22: 239.97 | G22: Card | H22: Refunded
A23: O-1022 | B23: C-0005 | C23: S-04 | D23: 2024-07-04 | E23: CAD | F23: CAD 7937.23 | G23: Cash | H23: Pending
A24: O-1023 | B24: C-0021 | C24: S-03 | D24: 1 Aug 2024 | E24: USD | F24: 6836.4 | G24: Card
A25: O-1024 | B25: C-0021 | C25: S-09 | D25: 1 Aug 2024 | E25: EUR | F25: EUR 786.96 | G25: Cash | H25: Completed
A26: O-1025 | B26: C-0018 | C26: S-06 | D26: 2025-07-19 | E26: USD | F26: 4124.96 | G26: UPI
A27: O-1026 | B27: C-0004 | C27: S-09 | D27: 1 Aug 2024 | E27: CAD | F27: 3506.17 | G27: Cash | H27: Pending
A28: O-1027 | B28: C-0013 | C28: S-03 | D28: 2024.07.23 | E28: EUR | F28: 7057.281 | G28: Card | H28: Pending
A29: O-1028 | B29: C-0004 | C29: S-02 | D29: 2024.07.14 | E29: USD | F29: 44.97 | G29: UPI | H29: Completed
A30: O-1029 | B30: C-0024 | C30: S-09 | D30: 2024.07.23 | E30: CAD | F30: 7327.7415 | G30: Cash | H30: Refunded
A31: O-1030 | B31: C-0025 | C31: S-05 | D31: 2025-06-29 | E31: CAD | F31: 29.98 | G31: Wallet
A32: O-1031 | B32: C-0008 | C32: S-04 | D32: 2024-11-07 | E32: USD | F32: 540.913 | G32: Cash | H32: Completed
A33: O-1032 | B33: C-0018 | C33: S-08 | D33: 2024.07.24 | E33: CAD | F33: 297.961 | G33: Wallet | H33: Pending
A34: O-1033 | B34: C-0007 | C34: S-05 | D34: 07/21/2024 | E34: CAD | F34: 2570.962 | G34: Cash | H34: Refunded
A35: O-1034 | B35: C-0002 | C35: S-09 | D35: 07/26/2024 | E35: EUR | F35: 47.4905 | G35: Cash | H35: Completed
A36: O-1035 | B36: C-0001 | C36: S-06 | D36: 2025-03-29 | E36: USD | F36: 4795.865 | G36: Card | H36: Pending
A37: O-1036 | B37: C-0005 | C37: S-01 | D37: 2024-07-02 | E37: USD | F37: 317.943 | G37: Wallet | H37: Completed
A38: O-1037 | B38: C-0012 | C38: S-05 | D38: 07/20/2024 | E38: EUR | F38: 605.916 | G38: Cash | H38: Refunded
A39: O-1038 | B39: C-0004 | C39: S-05 | D39: 2025-02-12 | E39: USD | F39: 56.9715 | G39: UPI | H39: Pending
A40: O-1039 | B40: C-0002 | C40: S-05 | D40: 2024-10-19 | E40: EUR | F40: 29.97 | G40: Card | H40: Refunded
...

Sheet OrderLines
A1: OrderLineID | B1: OrderID | C1: ProductID | D1: Quantity | E1: UnitPrice | F1: Discount | G1: LineAmount
A2: OL-84365 | B2: O-1001 | C2: P-121 | D2: 2 | E2: =VLOOKUP(OrderLines!$C2,Products!$A$1:$G$27,5,FALSE) -> EUR 899.00 | F2: 5 % | G2: 123.45
A3: OL-10892 | B3: O-1001 | C3: P-110 | D3: 2 | E3: =VLOOKUP(OrderLines!$C3,Products!$A$1:$G$27,5,FALSE) -> USD 39.99 | F3: 0%
A4: OL-58853 | B4: O-1002 | C4: P-117 | D4: two | E4: =VLOOKUP(OrderLines!$C4,Products!$A$1:$G$27,5,FALSE) -> USD 129.99 | F4: 5 % | G4: 123.45
A5: OL-22622 | B5: O-1002 | C5: P-111 | D5: 1 | E5: =VLOOKUP(OrderLines!$C5,Products!$A$1:$G$27,5,FALSE) -> USD 69.99 | G5: 1.234,56
A6: OL-37195 | B6: O-1002 | C6: P-104 | D6: 3 | E6: =VLOOKUP(OrderLines!$C6,Products!$A$1:$G$27,5,FALSE) -> EUR 19.99 | G6: 123.45
A7: OL-38411 | B7: O-1003 | C7: P-111 | D7: 2 | E7: =VLOOKUP(OrderLines!$C7,Products!$A$1:$G$27,5,FALSE) -> USD 69.99 | F7: 5 % | G7: 1.234,56
A8: OL-19771 | B8: O-1003 | C8: P-102 | D8: 1 | E8: =VLOOKUP(OrderLines!$C8,Products!$A$1:$G$27,5,FALSE) -> USD 2499.00 | F8: 5 % | G8: 1.234,56
A9: OL-70500 | B9: O-1004 | C9: P-109 | D9: 3 pcs | E9: =VLOOKUP(OrderLines!$C9,Products!$A$1:$G$27,5,FALSE) -> USD 49.99 | F9: 5 % | G9: 123.45
A10: OL-20698 | B10: O-1004 | C10: P-113 | D10: 3 pcs | E10: =VLOOKUP(OrderLines!$C10,Products!$A$1:$G$27,5,FALSE) -> USD 59.99
A11: OL-31948 | B11: O-1005 | C11: P-113 | D11: 3 | E11: =VLOOKUP(OrderLines!$C11,Products!$A$1:$G$27,5,FALSE) -> USD 59.99 | F11: 10% | G11: 1.234,56
A12: OL-75725 | B12: O-1006 | C12: P-114 | D12: 2 | E12: =VLOOKUP(OrderLines!$C12,Products!$A$1:$G$27,5,FALSE) -> USD 79.99 | F12: 5 % | G12: 1.234,56
A13: OL-75428 | B13: O-1006 | C13: P-107 | D13: 3 | E13: =VLOOKUP(OrderLines!$C13,Products!$A$1:$G$27,5,FALSE) -> USD 59.00 | G13: 123.45
A14: OL-79177 | B14: O-1007 | C14: P-110 | D14: 4 | E14: =VLOOKUP(OrderLines!$C14,Products!$A$1:$G$27,5,FALSE) -> USD 39.99 | F14: 5 % | G14: 1.234,56
A15: OL-38860 | B15: O-1007 | C15: P-119 | D15: two | E15: =VLOOKUP(OrderLines!$C15,Products!$A$1:$G$27,5,FALSE) -> USD 29.99 | G15: 123.45
A16: OL-19696 | B16: O-1007 | C16: P-104 | D16: 1 | E16: =VLOOKUP(OrderLines!$C16,Products!$A$1:$G$27,5,FALSE) -> EUR 19.99 | F16: 0% | G16: 123.45
A17: OL-92440 | B17: O-1008 | C17: P-103 | D17: 2 | E17: =VLOOKUP(OrderLines!$C17,Products!$A$1:$G$27,5,FALSE) -> USD 79.99 | G17: 123.45
A18: OL-97763 | B18: O-1008 | C18: P-118 | D18: 3 pcs | E18: =VLOOKUP(OrderLines!$C18,Products!$A$1:$G$27,5,FALSE) -> USD 39.99
A19: OL-31280 | B19: O-1009 | C19: P-116 | D19: 3 pcs | E19: =VLOOKUP(OrderLines!$C19,Products!$A$1:$G$27,5,FALSE) -> USD 129.99 | F19: 0% | G19: 123.45
A20: OL-22713 | B20: O-1010 | C20: P-110 | D20: two | E20: =VLOOKUP(OrderLines!$C20,Products!$A$1:$G$27,5,FALSE) -> USD 39.99 | F20: 5 % | G20: 1.234,56
A21: OL-59211 | B21: O-1011 | C21: P-119 | D21: 4 | E21: =VLOOKUP(OrderLines!$C21,Products!$A$1:$G$27,5,FALSE) -> USD 29.99 | F21: 5 % | G21: 1.234,56
A22: OL-43382 | B22: O-1011 | C22: P-121 | D22: 3 | E22: =VLOOKUP(OrderLines!$C22,Products!$A$1:$G$27,5,FALSE) -> EUR 899.00 | G22: 123.45
A23: OL-84680 | B23: O-1012 | C23: P-108 | D23: 4 | E23: =VLOOKUP(OrderLines!$C23,Products!$A$1:$G$27,5,FALSE) -> USD 25.00 | F23: 0% | G23: 1.234,56
A24: OL-82741 | B24: O-1013 | C24: P-117 | D24: 2 | E24: =VLOOKUP(OrderLines!$C24,Products!$A$1:$G$27,5,FALSE) -> USD 129.99 | F24: 0%
A25: OL-96688 | B25: O-1013 | C25: P-122 | D25: 1 | E25: =VLOOKUP(OrderLines!$C25,Products!$A$1:$G$27,5,FALSE) -> USD 1899.00 | F25: 5 % | G25: 1.234,56
A26: OL-28246 | B26: O-1014 | C26: P-108 | D26: 4 | E26: =VLOOKUP(OrderLines!$C26,Products!$A$1:$G$27,5,FALSE) -> USD 25.00 | G26: 123.45
A27: OL-67134 | B27: O-1015 | C27: P-103 | D27: 1 | E27: =VLOOKUP(OrderLines!$C27,Products!$A$1:$G$27,5,FALSE) -> USD 79.99 | F27: 5 % | G27: 1.234,56
A28: OL-36182 | B28: O-1015 | C28: P-124 | D28: 1 | E28: =VLOOKUP(OrderLines!$C28,Products!$A$1:$G$27,5,FALSE) -> USD 14.99 | F28: 5 %
A29: OL-65966 | B29: O-1015 | C29: P-108 | D29: 3 | E29: =VLOOKUP(OrderLines!$C29,Products!$A$1:$G$27,5,FALSE) -> USD 25.00 | F29: 5 %
A30: OL-91496 | B30: O-1016 | C30: P-120 | D30: two | E30: =VLOOKUP(OrderLines!$C30,Products!$A$1:$G$27,5,FALSE) -> USD 9.99 | F30: 0%
A31: OL-33036 | B31: O-1016 | C31: P-108 | D31: 1 | E31: =VLOOKUP(OrderLines!$C31,Products!$A$1:$G$27,5,FALSE) -> USD 25.00 | F31: 0% | G31: 123.45
A32: OL-94242 | B32: O-1017 | C32: P-106 | D32: two | E32: =VLOOKUP(OrderLines!$C32,Products!$A$1:$G$27,5,FALSE) -> USD 89.00 | F32: 5 % | G32: 1.234,56
A33: OL-26262 | B33: O-1017 | C33: P-124 | D33: 3 | E33: =VLOOKUP(OrderLines!$C33,Products!$A$1:$G$27,5,FALSE) -> USD 14.99 | F33: 10%
A34: OL-24814 | B34: O-1017 | C34: P-104 | D34: 2 | E34: =VLOOKUP(OrderLines!$C34,Products!$A$1:$G$27,5,FALSE) -> EUR 19.99 | F34: 0%
A35: OL-14041 | B35: O-1018 | C35: P-117 | D35: 4 | E35: =VLOOKUP(OrderLines!$C35,Products!$A$1:$G$27,5,FALSE) -> USD 129.99 | F35: 10% | G35: 123.45
A36: OL-36891 | B36: O-1018 | C36: P-108 | D36: 3 pcs | E36: =VLOOKUP(OrderLines!$C36,Products!$A$1:$G$27,5,FALSE) -> USD 25.00 | G36: 123.45
A37: OL-97242 | B37: O-1019 | C37: P-115 | D37: 3 | E37: =VLOOKUP(OrderLines!$C37,Products!$A$1:$G$27,5,FALSE) -> USD 129.99 | F37: 5 % | G37: 123.45
A38: OL-99312 | B38: O-1019 | C38: P-111 | D38: two | E38: =VLOOKUP(OrderLines!$C38,Products!$A$1:$G$27,5,FALSE) -> USD 69.99 | F38: 10%
A39: OL-90250 | B39: O-1020 | C39: P-106 | D39: 3 | E39: =VLOOKUP(OrderLines!$C39,Products!$A$1:$G$27,5,FALSE) -> USD 89.00 | F39: 5 %
A40: OL-77373 | B40: O-1021 | C40: P-103 | D40: 3 | E40: =VLOOKUP(OrderLines!$C40,Products!$A$1:$G$27,5,FALSE) -> USD 79.99 | G40: 123.45
...
